submitit ERROR (2024-01-04 20:14:28,233) - Submitted job triggered an exception
Traceback (most recent call last):
  File "/usr/lib/python3.8/runpy.py", line 194, in _run_module_as_main
    return _run_code(code, main_globals, None,
  File "/usr/lib/python3.8/runpy.py", line 87, in _run_code
    exec(code, run_globals)
  File "/home/mohammed/seg/lib/python3.8/site-packages/submitit/core/_submit.py", line 11, in <module>
    submitit_main()
  File "/home/mohammed/seg/lib/python3.8/site-packages/submitit/core/submission.py", line 76, in submitit_main
    process_job(args.folder)
  File "/home/mohammed/seg/lib/python3.8/site-packages/submitit/core/submission.py", line 69, in process_job
    raise error
  File "/home/mohammed/seg/lib/python3.8/site-packages/submitit/core/submission.py", line 55, in process_job
    result = delayed.result()
  File "/home/mohammed/seg/lib/python3.8/site-packages/submitit/core/utils.py", line 133, in result
    self._result = self.function(*self.args, **self.kwargs)
  File "run_with_submitit_finetune.py", line 64, in __call__
    run_class_finetuning.main(self.args, self.parser)
  File "/mnt/c/Users/Moham/Desktop/Harmony/unilm/beit/run_class_finetuning.py", line 563, in main
    train_stats = train_one_epoch(
  File "/mnt/c/Users/Moham/Desktop/Harmony/unilm/beit/engine_for_finetuning.py", line 71, in train_one_epoch
    samples, targets = mixup_fn(samples, targets)
  File "/home/mohammed/seg/lib/python3.8/site-packages/timm/data/mixup.py", line 210, in __call__
    assert len(x) % 2 == 0, 'Batch size should be even when using this'
AssertionError: Batch size should be even when using this
